Workbook

Sheet Master Dashboard
B1: MASTER DASHBOARD — DISTRICT PRIORITY AGENDA REVIEW, LUDHIANA
B2: Auto roll-up | Data as on 05-06-2026 | Cadence: every 3–4 days / before each weekly review
B3: ⚙ Auto-Flag Threshold (× Flag-Bar for achievement rules):
B4: 1 | C4: 1.00 = flag anyone below the Flag-Bar; lower (e.g. 0.90) for stricter.
A6: # | B6: Officer / Tab | C6: Total KPIs | D6: Completed | E6: On Track | F6: In Progress | G6: Pending/Blocked | H6: Not Started | I6: % Done | J6: 🔴 Flags
A7: 1 | B7: ADC (G) | C7: =COUNTIF('ADC (G)'!K3:K1997,"?*") -> 111 | D7: =COUNTIF('ADC (G)'!K3:K1997,"Completed") -> 1 | E7: =COUNTIF('ADC (G)'!K3:K1997,"On Track") -> 10 | F7: =COUNTIF('ADC (G)'!K3:K1997,"In Progress") -> 82 | G7: =COUNTIF('ADC (G)'!K3:K1997,"Pending/Blocked") -> 18 | H7: =COUNTIF('ADC (G)'!K3:K1997,"Not Started") -> 0 | I7: =IF(C7=0,0,(D7+E7)/C7) -> 0.099099099 | J7: =COUNTIF('ADC (G)'!L3:L1997,"*🔴*") -> 54
A8: 2 | B8: ADC (RD) | C8: =COUNTIF('ADC (RD)'!K3:K2000,"?*") -> 71 | D8: =COUNTIF('ADC (RD)'!K3:K2000,"Completed") -> 4 | E8: =COUNTIF('ADC (RD)'!K3:K2000,"On Track") -> 2 | F8: =COUNTIF('ADC (RD)'!K3:K2000,"In Progress") -> 44 | G8: =COUNTIF('ADC (RD)'!K3:K2000,"Pending/Blocked") -> 19 | H8: =COUNTIF('ADC (RD)'!K3:K2000,"Not Started") -> 2 | I8: =IF(C8=0,0,(D8+E8)/C8) -> 0.084507042 | J8: =COUNTIF('ADC (RD)'!L3:L2000,"*🔴*") -> 36
A9: 3 | B9: ADC (UD) | C9: =COUNTIF('ADC (UD)'!K3:K2000,"?*") -> 9 | D9: =COUNTIF('ADC (UD)'!K3:K2000,"Completed") -> 0 | E9: =COUNTIF('ADC (UD)'!K3:K2000,"On Track") -> 0 | F9: =COUNTIF('ADC (UD)'!K3:K2000,"In Progress") -> 6 | G9: =COUNTIF('ADC (UD)'!K3:K2000,"Pending/Blocked") -> 3 | H9: =COUNTIF('ADC (UD)'!K3:K2000,"Not Started") -> 0 | I9: =IF(C9=0,0,(D9+E9)/C9) -> 0 | J9: =COUNTIF('ADC (UD)'!L3:L2000,"*🔴*") -> 2
A10: 4 | B10: ADC (J) | C10: =COUNTIF('ADC (J)'!K3:K2000,"?*") -> 12 | D10: =COUNTIF('ADC (J)'!K3:K2000,"Completed") -> 1 | E10: =COUNTIF('ADC (J)'!K3:K2000,"On Track") -> 0 | F10: =COUNTIF('ADC (J)'!K3:K2000,"In Progress") -> 5 | G10: =COUNTIF('ADC (J)'!K3:K2000,"Pending/Blocked") -> 6 | H10: =COUNTIF('ADC (J)'!K3:K2000,"Not Started") -> 0 | I10: =IF(C10=0,0,(D10+E10)/C10) -> 0.083333333 | J10: =COUNTIF('ADC (J)'!L3:L2000,"*🔴*") -> 3
A11: 5 | B11: ADC (K) | C11: =COUNTIF('ADC (K)'!K3:K2000,"?*") -> 10 | D11: =COUNTIF('ADC (K)'!K3:K2000,"Completed") -> 0 | E11: =COUNTIF('ADC (K)'!K3:K2000,"On Track") -> 0 | F11: =COUNTIF('ADC (K)'!K3:K2000,"In Progress") -> 6 | G11: =COUNTIF('ADC (K)'!K3:K2000,"Pending/Blocked") -> 4 | H11: =COUNTIF('ADC (K)'!K3:K2000,"Not Started") -> 0 | I11: =IF(C11=0,0,(D11+E11)/C11) -> 0 | J11: =COUNTIF('ADC (K)'!L3:L2000,"*🔴*") -> 5
A12: 6 | B12: CMFO | C12: =COUNTIF(CMFO!K3:K2000,"?*") -> 39 | D12: =COUNTIF(CMFO!K3:K2000,"Completed") -> 0 | E12: =COUNTIF(CMFO!K3:K2000,"On Track") -> 0 | F12: =COUNTIF(CMFO!K3:K2000,"In Progress") -> 13 | G12: =COUNTIF(CMFO!K3:K2000,"Pending/Blocked") -> 26 | H12: =COUNTIF(CMFO!K3:K2000,"Not Started") -> 0 | I12: =IF(C12=0,0,(D12+E12)/C12) -> 0 | J12: =COUNTIF(CMFO!L3:L2000,"*🔴*") -> 20
A13: 7 | B13: AC (G) | C13: =COUNTIF('AC (G)'!K3:K2000,"?*") -> 30 | D13: =COUNTIF('AC (G)'!K3:K2000,"Completed") -> 3 | E13: =COUNTIF('AC (G)'!K3:K2000,"On Track") -> 1 | F13: =COUNTIF('AC (G)'!K3:K2000,"In Progress") -> 18 | G13: =COUNTIF('AC (G)'!K3:K2000,"Pending/Blocked") -> 8 | H13: =COUNTIF('AC (G)'!K3:K2000,"Not Started") -> 0 | I13: =IF(C13=0,0,(D13+E13)/C13) -> 0.13333333 | J13: =COUNTIF('AC (G)'!L3:L2000,"*🔴*") -> 11
A14: 8 | B14: DRO | C14: =COUNTIF(DRO!K3:K2000,"?*") -> 18 | D14: =COUNTIF(DRO!K3:K2000,"Completed") -> 0 | E14: =COUNTIF(DRO!K3:K2000,"On Track") -> 0 | F14: =COUNTIF(DRO!K3:K2000,"In Progress") -> 13 | G14: =COUNTIF(DRO!K3:K2000,"Pending/Blocked") -> 5 | H14: =COUNTIF(DRO!K3:K2000,"Not Started") -> 0 | I14: =IF(C14=0,0,(D14+E14)/C14) -> 0 | J14: =COUNTIF(DRO!L3:L2000,"*🔴*") -> 5
A15: 9 | B15: SDM Samrala | C15: =COUNTIF('SDM Samrala'!K3:K2000,"?*") -> 6 | D15: =COUNTIF('SDM Samrala'!K3:K2000,"Completed") -> 0 | E15: =COUNTIF('SDM Samrala'!K3:K2000,"On Track") -> 0 | F15: =COUNTIF('SDM Samrala'!K3:K2000,"In Progress") -> 1 | G15: =COUNTIF('SDM Samrala'!K3:K2000,"Pending/Blocked") -> 5 | H15: =COUNTIF('SDM Samrala'!K3:K2000,"Not Started") -> 0 | I15: =IF(C15=0,0,(D15+E15)/C15) -> 0 | J15: =COUNTIF('SDM Samrala'!L3:L2000,"*🔴*") -> 2
A16: 10 | B16: SDM Jagraon | C16: =COUNTIF('SDM Jagraon'!K3:K2000,"?*") -> 6 | D16: =COUNTIF('SDM Jagraon'!K3:K2000,"Completed") -> 0 | E16: =COUNTIF('SDM Jagraon'!K3:K2000,"On Track") -> 0 | F16: =COUNTIF('SDM Jagraon'!K3:K2000,"In Progress") -> 2 | G16: =COUNTIF('SDM Jagraon'!K3:K2000,"Pending/Blocked") -> 4 | H16: =COUNTIF('SDM Jagraon'!K3:K2000,"Not Started") -> 0 | I16: =IF(C16=0,0,(D16+E16)/C16) -> 0 | J16: =COUNTIF('SDM Jagraon'!L3:L2000,"*🔴*") -> 1
A17: 11 | B17: SDM Payal | C17: =COUNTIF('SDM Payal'!K3:K2000,"?*") -> 6 | D17: =COUNTIF('SDM Payal'!K3:K2000,"Completed") -> 0 | E17: =COUNTIF('SDM Payal'!K3:K2000,"On Track") -> 0 | F17: =COUNTIF('SDM Payal'!K3:K2000,"In Progress") -> 5 | G17: =COUNTIF('SDM Payal'!K3:K2000,"Pending/Blocked") -> 1 | H17: =COUNTIF('SDM Payal'!K3:K2000,"Not Started") -> 0 | I17: =IF(C17=0,0,(D17+E17)/C17) -> 0 | J17: =COUNTIF('SDM Payal'!L3:L2000,"*🔴*") -> 1
A18: 12 | B18: SDM East | C18: =COUNTIF('SDM East'!K3:K2000,"?*") -> 9 | D18: =COUNTIF('SDM East'!K3:K2000,"Completed") -> 0 | E18: =COUNTIF('SDM East'!K3:K2000,"On Track") -> 0 | F18: =COUNTIF('SDM East'!K3:K2000,"In Progress") -> 3 | G18: =COUNTIF('SDM East'!K3:K2000,"Pending/Blocked") -> 6 | H18: =COUNTIF('SDM East'!K3:K2000,"Not Started") -> 0 | I18: =IF(C18=0,0,(D18+E18)/C18) -> 0 | J18: =COUNTIF('SDM East'!L3:L2000,"*🔴*") -> 0
A19: 13 | B19: SDM West | C19: =COUNTIF('SDM West'!K3:K2000,"?*") -> 10 | D19: =COUNTIF('SDM West'!K3:K2000,"Completed") -> 0 | E19: =COUNTIF('SDM West'!K3:K2000,"On Track") -> 0 | F19: =COUNTIF('SDM West'!K3:K2000,"In Progress") -> 5 | G19: =COUNTIF('SDM West'!K3:K2000,"Pending/Blocked") -> 5 | H19: =COUNTIF('SDM West'!K3:K2000,"Not Started") -> 0 | I19: =IF(C19=0,0,(D19+E19)/C19) -> 0 | J19: =COUNTIF('SDM West'!L3:L2000,"*🔴*") -> 3
A20: 14 | B20: SDM Raikot | C20: =COUNTIF('SDM Raikot'!K3:K2000,"?*") -> 7 | D20: =COUNTIF('SDM Raikot'!K3:K2000,"Completed") -> 1 | E20: =COUNTIF('SDM Raikot'!K3:K2000,"On Track") -> 0 | F20: =COUNTIF('SDM Raikot'!K3:K2000,"In Progress") -> 4 | G20: =COUNTIF('SDM Raikot'!K3:K2000,"Pending/Blocked") -> 2 | H20: =COUNTIF('SDM Raikot'!K3:K2000,"Not Started") -> 0 | I20: =IF(C20=0,0,(D20+E20)/C20) -> 0.14285714 | J20: =COUNTIF('SDM Raikot'!L3:L2000,"*🔴*") -> 1
A21: 15 | B21: RTA | C21: =COUNTIF(RTA!K3:K2000,"?*") -> 5 | D21: =COUNTIF(RTA!K3:K2000,"Completed") -> 0 | E21: =COUNTIF(RTA!K3:K2000,"On Track") -> 0 | F21: =COUNTIF(RTA!K3:K2000,"In Progress") -> 5 | G21: =COUNTIF(RTA!K3:K2000,"Pending/Blocked") -> 0 | H21: =COUNTIF(RTA!K3:K2000,"Not Started") -> 0 | I21: =IF(C21=0,0,(D21+E21)/C21) -> 0 | J21: =COUNTIF(RTA!L3:L2000,"*🔴*") -> 0
B22: DISTRICT TOTAL | C22: =SUM(C7:C21) -> 349 | D22: =SUM(D7:D21) -> 10 | E22: =SUM(E7:E21) -> 13 | F22: =SUM(F7:F21) -> 212 | G22: =SUM(G7:G21) -> 112 | H22: =SUM(H7:H21) -> 2 | I22: =IF(C22=0,0,(D22+E22)/C22) -> 0.065902579 | J22: =SUM(J7:J21) -> 144
B24: WEEKLY MEETING FOCUS
B25: • Each officer tab shows SCHEMES (metrics) first, then PRIORITY TASKS — take highest 🔴 Flags + Pending first.
B26: • Each scheme opens with a 📊 SNAPSHOT band of headline totals.
B27: • Filter any tab's 'Auto-Flag' for 🔴 to list that officer's at-risk items.
B28: • Connect officer workbooks via the 'Data Connections' tab to make figures auto-refresh.

Sheet Instructions
B1: OFFICE OF THE DEPUTY COMMISSIONER-CUM-DISTRICT MAGISTRATE, LUDHIANA
B2: MASTER PRIORITY AGENDA — REVIEW & TRACKING (DC consolidated)
B4: Purpose | C4: DC's consolidated view of all priority agendas. Data is fed up from each officer's own workbook (see 'Data Connections' tab). The DC runs the weekly review from here + the Master Dashboard.
B5: Two-tier design | C5: Each officer maintains their OWN workbook (one tab per scheme + a Priority Tasks tab). Those cells link into this master via IMPORTRANGE. Update once in the officer workbook → flows up here.
B7: Each officer tab is split | C7: ▣ SCHEMES (metric-based) — quantitative agendas with targets, shown FIRST under a blue banner. ▣ PRIORITY TASKS (qualitative) — assigned tasks, shown BELOW under a gold banner.
B9: 📊 SNAPSHOT band | C9: Each scheme opens with light-blue bold headline totals (e.g. Rangla P-I: Total/Started/In Progress/Completed/Not Started).
B10: Auto bottom-performer flag | C10: 🔴 LOW (below Flag-Bar) / 🔴 HIGH (above pendency ceiling). Threshold on Master Dashboard B4. Manual override via 'Bottom Performer' column (Auto/Yes/No).
B11: Linking | C11: Until officer workbook URLs are pasted (Data Connections tab), the figures here are the 04–05 Jun headline values. After linking, Current/Status/Flag auto-refresh from each officer workbook.
B12: MLA Works | C12: MLA constituency works remain in the separate linked MLA Works List sheet (unchanged).

Sheet ADC (G)
A1: ADC (G) — Priority Agenda Review | DC Ludhiana (MASTER)
A2: Sr | B2: Priority Agenda | C2: KPI / Metric | D2: Concerned Officer / Unit | E2: Target / Total | F2: Flag Bar | G2: Last Value | H2: Current Value | I2: Change | J2: Achieved % | K2: Status | L2: Auto-Flag | M2: Bottom Performer | N2: Updated By | O2: Update Date | P2: Remarks / Context / Pending Action | Q2: Rule | R2: Key
A3: ▣ SCHEMES — metric-based (fed from officer workbook)
A4: 1 | B4: MMSBY — Sehat Bima Yojna | C4: 📊 Total cards made — cumulative 26 May–04 Jun | H4: 7669 | P4: District total across all ACs incl. not-mapped (5,917 dept-channel + 1,752 Sewa-Kendra).
C5: 📊 Cards made today — 04 Jun | H5: 921 | P5: All channels combined on 04 Jun (674 dept + 247 Sewa-Kendra).
C6: 📊 Cards NOT mapped to any AC | H6: 186 | P6: Generated but not yet linked to an Assembly Constituency — to be reassigned.
C7: 📊 Nodals yet to fill Phase-18 sheet | H7: 6 | P7: Sahnewal, Payal, Khanna, Dakha, Samrala, Atam Nagar.
C8: Total cards — 04 Jun (single day) | D8: cards | H8: 921 | I8: =IF(AND(ISNUMBER(G8),ISNUMBER(H8)),H8-G8,"") | J8: =IF(AND(ISNUMBER(E8),E8>0,ISNUMBER(H8)),H8/E8,"") | K8: In Progress | L8: =IF(M8="Yes","🔴 BOTTOM",IF(M8="No","✓ Cleared",IF(Q8="MIN",IF(AND(ISNUMBER(F8),ISNUMBER(H8)),IF(H8<F8*'Master Dashboard'!$B$4,"🔴 LOW",""),""),IF(Q8="MAX",IF(AND(ISNUMBER(F8),ISNUMBER(H8)),IF(H8>F8,"🔴 HIGH",""),""),"")))) | M8: Auto | N8: Gov Cell (report) | O8: 05-06-2026 | P8: 674 dept + 247 SK | R8: ADCG-001
C9: Total cards — cumulative 26 May–04 Jun | D9: cards | H9: 7669 | I9: =IF(AND(ISNUMBER(G9),ISNUMBER(H9)),H9-G9,"") | J9: =IF(AND(ISNUMBER(E9),E9>0,ISNUMBER(H9)),H9/E9,"") | K9: In Progress | L9: =IF(M9="Yes","🔴 BOTTOM",IF(M9="No","✓ Cleared",IF(Q9="MIN",IF(AND(ISNUMBER(F9),ISNUMBER(H9)),IF(H9<F9*'Master Dashboard'!$B$4,"🔴 LOW",""),""),IF(Q9="MAX",IF(AND(ISNUMBER(F9),ISNUMBER(H9)),IF(H9>F9,"🔴 HIGH",""),""),"")))) | M9: Auto | N9: Gov Cell (report) | O9: 05-06-2026 | P9: 5917 dept + 1752 SK | R9: ADCG-002
C10: Channel — DM CSC (04 Jun) | D10: cards | G10: 832 | H10: 795 | I10: =IF(AND(ISNUMBER(G10),ISNUMBER(H10)),H10-G10,"") -> -37 | J10: =IF(AND(ISNUMBER(E10),E10>0,ISNUMBER(H10)),H10/E10,"") | K10: In Progress | L10: =IF(M10="Yes","🔴 BOTTOM",IF(M10="No","✓ Cleared",IF(Q10="MIN",IF(AND(ISNUMBER(F10),ISNUMBER(H10)),IF(H10<F10*'Master Dashboard'!$B$4,"🔴 LOW",""),""),IF(Q10="MAX",IF(AND(ISNUMBER(F10),ISNUMBER(H10)),IF(H10>F10,"🔴 HIGH",""),""),"")))) | M10: Auto | N10: Gov Cell (report) | O10: 05-06-2026 | P10: Prev day 832 — Cards generated via DM-CSC (Common Service Centre) channel that day. | R10: ADCG-003
C11: Channel — Dr Cooperation / PACS (04 Jun) | D11: cards | G11: 18 | H11: 20 | I11: =IF(AND(ISNUMBER(G11),ISNUMBER(H11)),H11-G11,"") -> 2 | J11: =IF(AND(ISNUMBER(E11),E11>0,ISNUMBER(H11)),H11/E11,"") | K11: In Progress | L11: =IF(M11="Yes","🔴 BOTTOM",IF(M11="No","✓ Cleared",IF(Q11="MIN",IF(AND(ISNUMBER(F11),ISNUMBER(H11)),IF(H11<F11*'Master Dashboard'!$B$4,"🔴 LOW",""),""),IF(Q11="MAX",IF(AND(ISNUMBER(F11),ISNUMBER(H11)),IF(H11>F11,"🔴 HIGH",""),""),"")))) | M11: Auto | N11: Gov Cell (report) | O11: 05-06-2026 | P11: Cards via Dr Cooperation / PACS societies that day. | R11: ADCG-004
C12: Channel — Agriculture Dept (04 Jun) | D12: cards | G12: 16 | H12: 19 | I12: =IF(AND(ISNUMBER(G12),ISNUMBER(H12)),H12-G12,"") -> 3 | J12: =IF(AND(ISNUMBER(E12),E12>0,ISNUMBER(H12)),H12/E12,"") | K12: In Progress | L12: =IF(M12="Yes","🔴 BOTTOM",IF(M12="No","✓ Cleared",IF(Q12="MIN",IF(AND(ISNUMBER(F12),ISNUMBER(H12)),IF(H12<F12*'Master Dashboard'!$B$4,"🔴 LOW",""),""),IF(Q12="MAX",IF(AND(ISNUMBER(F12),ISNUMBER(H12)),IF(H12>F12,"🔴 HIGH",""),""),"")))) | M12: Auto | N12: Gov Cell (report) | O12: 05-06-2026 | P12: Cards via Agriculture Dept that day. | R12: ADCG-005
C13: Channel — ASHA cards (04 Jun) | D13: cards | G13: 511 | H13: 582 | I13: =IF(AND(ISNUMBER(G13),ISNUMBER(H13)),H13-G13,"") -> 71 | J13: =IF(AND(ISNUMBER(E13),E13>0,ISNUMBER(H13)),H13/E13,"") | K13: In Progress | L13: =IF(M13="Yes","🔴 BOTTOM",IF(M13="No","✓ Cleared",IF(Q13="MIN",IF(AND(ISNUMBER(F13),ISNUMBER(H13)),IF(H13<F13*'Master Dashboard'!$B$4,"🔴 LOW",""),""),IF(Q13="MAX",IF(AND(ISNUMBER(F13),ISNUMBER(H13)),IF(H13>F13,"🔴 HIGH",""),""),"")))) | M13: Auto | N13: Gov Cell (report) | O13: 05-06-2026 | P13: Sharp drop since 08 May (was 3961 on 28 Apr) — Cards by ASHA workers that day. | R13: ADCG-006
C14: Channel — Hospital total (04 Jun) | D14: cards | G14: 51 | H14: 40 | I14: =IF(AND(ISNUMBER(G14),ISNUMBER(H14)),H14-G14,"") -> -11 | J14: =IF(AND(ISNUMBER(E14),E14>0,ISNUMBER(H14)),H14/E14,"") | K14: In Progress | L14: =IF(M14="Yes","🔴 BOTTOM",IF(M14="No","✓ Cleared",IF(Q14="MIN",IF(AND(ISNUMBER(F14),ISNUMBER(H14)),IF(H14<F14*'Master Dashboard'!$B$4,"🔴 LOW",""),""),IF(Q14="MAX",IF(AND(ISNUMBER(F14),ISNUMBER(H14)),IF(H14>F14,"🔴 HIGH",""),""),"")))) | M14: Auto | N14: Gov Cell (report) | O14: 05-06-2026 | P14: Govt 33 / Private 7 — Cards issued at hospitals that day (Govt + Private). | R14: ADCG-007
C15: Govt hospital cards (04 Jun) | D15: cards | G15: 47 | H15: 33 | I15: =IF(AND(ISNUMBER(G15),ISNUMBER(H15)),H15-G15,"") -> -14 | J15: =IF(AND(ISNUMBER(E15),E15>0,ISNUMBER(H15)),H15/E15,"") | K15: In Progress | L15: =IF(M15="Yes","🔴 BOTTOM",IF(M15="No","✓ Cleared",IF(Q15="MIN",IF(AND(ISNUMBER(F15),ISNUMBER(H15)),IF(H15<F15*'Master Dashboard'!$B$4,"🔴 LOW",""),""),IF(Q15="MAX",IF(AND(ISNUMBER(F15),ISNUMBER(H15)),IF(H15>F15,"🔴 HIGH",""),""),"")))) | M15: Auto | N15: Gov Cell (report) | O15: 05-06-2026 | P15: Issuance at govt facilities (DH/SDH/AAC) that day. | R15: ADCG-008
C16: Private hospital cards (04 Jun) | D16: cards | E16: 20 | F16: 15 | G16: 2 | H16: 7 | I16: =IF(AND(ISNUMBER(G16),ISNUMBER(H16)),H16-G16,"") -> 5 | J16: =IF(AND(ISNUMBER(E16),E16>0,ISNUMBER(H16)),H16/E16,"") -> 0.35 | K16: In Progress | L16: =IF(M16="Yes","🔴 BOTTOM",IF(M16="No","✓ Cleared",IF(Q16="MIN",IF(AND(ISNUMBER(F16),ISNUMBER(H16)),IF(H16<F16*'Master Dashboard'!$B$4,"🔴 LOW",""),""),IF(Q16="MAX",IF(AND(ISNUMBER(F16),ISNUMBER(H16)),IF(H16>F16,"🔴 HIGH",""),""),"")))) -> 🔴 LOW | M16: Auto | N16: Gov Cell (report) | O16: 05-06-2026 | P16: Private penetration low — Private-hospital issuance that day — low penetration. | Q16: MIN | R16: ADCG-009
C17: Not-Mapped cards (to reconcile) | D17: cards | F17: 100 | H17: 186 | I17: =IF(AND(ISNUMBER(G17),ISNUMBER(H17)),H17-G17,"") | J17: =IF(AND(ISNUMBER(E17),E17>0,ISNUMBER(H17)),H17/E17,"") | K17: Pending/Blocked | L17: =IF(M17="Yes","🔴 BOTTOM",IF(M17="No","✓ Cleared",IF(Q17="MIN",IF(AND(ISNUMBER(F17),ISNUMBER(H17)),IF(H17<F17*'Master Dashboard'!$B$4,"🔴 LOW",""),""),IF(Q17="MAX",IF(AND(ISNUMBER(F17),ISNUMBER(H17)),IF(H17>F17,"🔴 HIGH",""),""),"")))) -> 🔴 HIGH | M17: Auto | N17: Gov Cell (report) | O17: 05-06-2026 | P17: Cumulative not-mapped pool | Q17: MAX | R17: ADCG-010
C18: Phase-18 sheet — nodals NOT filled | D18: nodals | E18: 6 | F18: 0 | H18: 6 | I18: =IF(AND(ISNUMBER(G18),ISNUMBER(H18)),H18-G18,"") | J18: =IF(AND(ISNUMBER(E18),E18>0,ISNUMBER(H18)),H18/E18,"") -> 1 | K18: Pending/Blocked | L18: =IF(M18="Yes","🔴 BOTTOM",IF(M18="No","✓ Cleared",IF(Q18="MIN",IF(AND(ISNUMBER(F18),ISNUMBER(H18)),IF(H18<F18*'Master Dashboard'!$B$4,"🔴 LOW",""),""),IF(Q18="MAX",IF(AND(ISNUMBER(F18),ISNUMBER(H18)),IF(H18>F18,"🔴 HIGH",""),""),"")))) -> 🔴 HIGH | M18: Auto | N18: Gov Cell (report) | O18: 05-06-2026 | P18: Sahnewal, Payal, Khanna, Dakha, Samrala, Atam Nagar | Q18: MAX | R18: ADCG-011
C19: Cards — Atam Nagar (04 Jun) | D19: cards | E19: 50 | F19: 50 | H19: 25 | I19: =IF(AND(ISNUMBER(G19),ISNUMBER(H19)),H19-G19,"") | J19: =IF(AND(ISNUMBER(E19),E19>0,ISNUMBER(H19)),H19/E19,"") -> 0.5 | K19: In Progress | L19: =IF(M19="Yes","🔴 BOTTOM",IF(M19="No","✓ Cleared",IF(Q19="MIN",IF(AND(ISNUMBER(F19),ISNUMBER(H19)),IF(H19<F19*'Master Dashboard'!$B$4,"🔴 LOW",""),""),IF(Q19="MAX",IF(AND(ISNUMBER(F19),ISNUMBER(H19)),IF(H19>F19,"🔴 HIGH",""),""),"")))) -> 🔴 LOW | M19: Auto | N19: Gov Cell (report) | O19: 05-06-2026 | P19: 25 cards + 0 SK — Total MMSBY cards in this AC on 04 Jun (incl. Sewa-Kendra). | Q19: MIN | R19: ADCG-012
C20: Cards — Dakha (04 Jun) | D20: cards | E20: 50 | F20: 50 | H20: 21 | I20: =IF(AND(ISNUMBER(G20),ISNUMBER(H20)),H20-G20,"") | J20: =IF(AND(ISNUMBER(E20),E20>0,ISNUMBER(H20)),H20/E20,"") -> 0.42 | K20: In Progress | L20: =IF(M20="Yes","🔴 BOTTOM",IF(M20="No","✓ Cleared",IF(Q20="MIN",IF(AND(ISNUMBER(F20),ISNUMBER(H20)),IF(H20<F20*'Master Dashboard'!$B$4,"🔴 LOW",""),""),IF(Q20="MAX",IF(AND(ISNUMBER(F20),ISNUMBER(H20)),IF(H20>F20,"🔴 HIGH",""),""),"")))) -> 🔴 LOW | M20: Auto | N20: Gov Cell (report) | O20: 05-06-2026 | P20: 21 cards + 0 SK — Total MMSBY cards in this AC on 04 Jun (incl. Sewa-Kendra). | Q20: MIN | R20: ADCG-013
C21: Cards — Gill (04 Jun) | D21: cards | E21: 50 | F21: 50 | H21: 79 | I21: =IF(AND(ISNUMBER(G21),ISNUMBER(H21)),H21-G21,"") | J21: =IF(AND(ISNUMBER(E21),E21>0,ISNUMBER(H21)),H21/E21,"") -> 1.58 | K21: In Progress | L21: =IF(M21="Yes","🔴 BOTTOM",IF(M21="No","✓ Cleared",IF(Q21="MIN",IF(AND(ISNUMBER(F21),ISNUMBER(H21)),IF(H21<F21*'Master Dashboard'!$B$4,"🔴 LOW",""),""),IF(Q21="MAX",IF(AND(ISNUMBER(F21),ISNUMBER(H21)),IF(H21>F21,"🔴 HIGH",""),""),"")))) | M21: Auto | N21: Gov Cell (report) | O21: 05-06-2026 | P21: 28 cards + 51 SK — Total MMSBY cards in this AC on 04 Jun (incl. Sewa-Kendra). | Q21: MIN | R21: ADCG-014
C22: Cards — Jagraon (04 Jun) | D22: cards | E22: 50 | F22: 50 | H22: 117 | I22: =IF(AND(ISNUMBER(G22),ISNUMBER(H22)),H22-G22,"") | J22: =IF(AND(ISNUMBER(E22),E22>0,ISNUMBER(H22)),H22/E22,"") -> 2.34 | K22: In Progress | L22: =IF(M22="Yes","🔴 BOTTOM",IF(M22="No","✓ Cleared",IF(Q22="MIN",IF(AND(ISNUMBER(F22),ISNUMBER(H22)),IF(H22<F22*'Master Dashboard'!$B$4,"🔴 LOW",""),""),IF(Q22="MAX",IF(AND(ISNUMBER(F22),ISNUMBER(H22)),IF(H22>F22,"🔴 HIGH",""),""),"")))) | M22: Auto | N22: Gov Cell (report) | O22: 05-06-2026 | P22: 68 cards + 49 SK — Total MMSBY cards in this AC on 04 Jun (incl. Sewa-Kendra). | Q22: MIN | R22: ADCG-015
C23: Cards — Khanna (04 Jun) | D23: cards | E23: 50 | F23: 50 | H23: 36 | I23: =IF(AND(ISNUMBER(G23),ISNUMBER(H23)),H23-G23,"") | J23: =IF(AND(ISNUMBER(E23),E23>0,ISNUMBER(H23)),H23/E23,"") -> 0.72 | K23: In Progress | L23: =IF(M23="Yes","🔴 BOTTOM",IF(M23="No","✓ Cleared",IF(Q23="MIN",IF(AND(ISNUMBER(F23),ISNUMBER(H23)),IF(H23<F23*'Master Dashboard'!$B$4,"🔴 LOW",""),""),IF(Q23="MAX",IF(AND(ISNUMBER(F23),ISNUMBER(H23)),IF(H23>F23,"🔴 HIGH",""),""),"")))) -> 🔴 LOW | M23: Auto | N23: Gov Cell (report) | O23: 05-06-2026 | P23: 36 cards + 0 SK — Total MMSBY cards in this AC on 04 Jun (incl. Sewa-Kendra). | Q23: MIN | R23: ADCG-016
C24: Cards — Ludhiana Central (04 Jun) | D24: cards | E24: 50 | F24: 50 | H24: 89 | I24: =IF(AND(ISNUMBER(G24),ISNUMBER(H24)),H24-G24,"") | J24: =IF(AND(ISNUMBER(E24),E24>0,ISNUMBER(H24)),H24/E24,"") -> 1.78 | K24: In Progress | L24: =IF(M24="Yes","🔴 BOTTOM",IF(M24="No","✓ Cleared",IF(Q24="MIN",IF(AND(ISNUMBER(F24),ISNUMBER(H24)),IF(H24<F24*'Master Dashboard'!$B$4,"🔴 LOW",""),""),IF(Q24="MAX",IF(AND(ISNUMBER(F24),ISNUMBER(H24)),IF(H24>F24,"🔴 HIGH",""),""),"")))) | M24: Auto | N24: Gov Cell (report) | O24: 05-06-2026 | P24: 53 cards + 36 SK — Total MMSBY cards in this AC on 04 Jun (incl. Sewa-Kendra). | Q24: MIN | R24: ADCG-017
C25: Cards — Ludhiana East (04 Jun) | D25: cards | E25: 50 | F25: 50 | H25: 62 | I25: =IF(AND(ISNUMBER(G25),ISNUMBER(H25)),H25-G25,"") | J25: =IF(AND(ISNUMBER(E25),E25>0,ISNUMBER(H25)),H25/E25,"") -> 1.24 | K25: In Progress | L25: =IF(M25="Yes","🔴 BOTTOM",IF(M25="No","✓ Cleared",IF(Q25="MIN",IF(AND(ISNUMBER(F25),ISNUMBER(H25)),IF(H25<F25*'Master Dashboard'!$B$4,"🔴 LOW",""),""),IF(Q25="MAX",IF(AND(ISNUMBER(F25),ISNUMBER(H25)),IF(H25>F25,"🔴 HIGH",""),""),"")))) | M25: Auto | N25: Gov Cell (report) | O25: 05-06-2026 | P25: 48 cards + 14 SK — Total MMSBY cards in this AC on 04 Jun (incl. Sewa-Kendra). | Q25: MIN | R25: ADCG-018
C26: Cards — Ludhiana North (04 Jun) | D26: cards | E26: 50 | F26: 50 | H26: 22 | I26: =IF(AND(ISNUMBER(G26),ISNUMBER(H26)),H26-G26,"") | J26: =IF(AND(ISNUMBER(E26),E26>0,ISNUMBER(H26)),H26/E26,"") -> 0.44 | K26: In Progress | L26: =IF(M26="Yes","🔴 BOTTOM",IF(M26="No","✓ Cleared",IF(Q26="MIN",IF(AND(ISNUMBER(F26),ISNUMBER(H26)),IF(H26<F26*'Master Dashboard'!$B$4,"🔴 LOW",""),""),IF(Q26="MAX",IF(AND(ISNUMBER(F26),ISNUMBER(H26)),IF(H26>F26,"🔴 HIGH",""),""),"")))) -> 🔴 LOW | M26: Auto | N26: Gov Cell (report) | O26: 05-06-2026 | P26: 19 cards + 3 SK — Total MMSBY cards in this AC on 04 Jun (incl. Sewa-Kendra). | Q26: MIN | R26: ADCG-019
C27: Cards — Ludhiana South (04 Jun) | D27: cards | E27: 50 | F27: 50 | H27: 15 | I27: =IF(AND(ISNUMBER(G27),ISNUMBER(H27)),H27-G27,"") | J27: =IF(AND(ISNUMBER(E27),E27>0,ISNUMBER(H27)),H27/E27,"") -> 0.3 | K27: In Progress | L27: =IF(M27="Yes","🔴 BOTTOM",IF(M27="No","✓ Cleared",IF(Q27="MIN",IF(AND(ISNUMBER(F27),ISNUMBER(H27)),IF(H27<F27*'Master Dashboard'!$B$4,"🔴 LOW",""),""),IF(Q27="MAX",IF(AND(ISNUMBER(F27),ISNUMBER(H27)),IF(H27>F27,"🔴 HIGH",""),""),"")))) -> 🔴 LOW | M27: Auto | N27: Gov Cell (report) | O27: 05-06-2026 | P27: 15 cards + 0 SK — Total MMSBY cards in this AC on 04 Jun (incl. Sewa-Kendra). | Q27: MIN | R27: ADCG-020
C28: Cards — Ludhiana West (04 Jun) | D28: cards | E28: 50 | F28: 50 | H28: 61 | I28: =IF(AND(ISNUMBER(G28),ISNUMBER(H28)),H28-G28,"") | J28: =IF(AND(ISNUMBER(E28),E28>0,ISNUMBER(H28)),H28/E28,"") -> 1.22 | K28: In Progress | L28: =IF(M28="Yes","🔴 BOTTOM",IF(M28="No","✓ Cleared",IF(Q28="MIN",IF(AND(ISNUMBER(F28),ISNUMBER(H28)),IF(H28<F28*'Master Dashboard'!$B$4,"🔴 LOW",""),""),IF(Q28="MAX",IF(AND(ISNUMBER(F28),ISNUMBER(H28)),IF(H28>F28,"🔴 HIGH",""),""),"")))) | M28: Auto | N28: Gov Cell (report) | O28: 05-06-2026 | P28: 60 cards + 1 SK — Total MMSBY cards in this AC on 04 Jun (incl. Sewa-Kendra). | Q28: MIN | R28: ADCG-021
C29: Cards — Payal (04 Jun) | D29: cards | E29: 50 | F29: 50 | H29: 28 | I29: =IF(AND(ISNUMBER(G29),ISNUMBER(H29)),H29-G29,"") | J29: =IF(AND(ISNUMBER(E29),E29>0,ISNUMBER(H29)),H29/E29,"") -> 0.56 | K29: In Progress | L29: =IF(M29="Yes","🔴 BOTTOM",IF(M29="No","✓ Cleared",IF(Q29="MIN",IF(AND(ISNUMBER(F29),ISNUMBER(H29)),IF(H29<F29*'Master Dashboard'!$B$4,"🔴 LOW",""),""),IF(Q29="MAX",IF(AND(ISNUMBER(F29),ISNUMBER(H29)),IF(H29>F29,"🔴 HIGH",""),""),"")))) -> 🔴 LOW | M29: Auto | N29: Gov Cell (report) | O29: 05-06-2026 | P29: 28 cards + 0 SK — Total MMSBY cards in this AC on 04 Jun (incl. Sewa-Kendra). | Q29: MIN | R29: ADCG-022
... C32: Cards — Samrala (04 Jun) | D32: cards | E32: 50 | F32: 50 | H32: 119 | I32: =IF(AND(ISNUMBER(G32),ISNUMBER(H32)),H32-G32,"") | J32: =IF(AND(ISNUMBER(E32),E32>0,ISNUMBER(H32)),H32/E32,"") -> 2.38 | K32: In Progress | L32: =IF(M32="Yes","🔴 BOTTOM",IF(M32="No","✓ Cleared",IF(Q32="MIN",IF(AND(ISNUMBER(F32),ISNUMBER(H32)),IF(H32<F32*'Master Dashboard'!$B$4,"🔴 LOW",""),""),IF(Q32="MAX",IF(AND(ISNUMBER(F32),ISNUMBER(H32)),IF(H32>F32,"🔴 HIGH",""),""),"")))) | M32: Auto | N32: Gov Cell (report) | O32: 05-06-2026 | P32: 81 cards + 38 SK — Total MMSBY cards in this AC on 04 Jun (incl. Sewa-Kendra). | Q32: MIN | R32: ADCG-025
A33: 2 | B33: AAC & SDH (Aam Aadmi Clinics / SDH) | C33: 📊 AAC Phase 8/9/10 — total sites | H33: 48 | P33: Inaugurated 17 | Work in progress 30 | Problematic 1.
C34: 📊 SHC→AAC Phase 11 — total sites | H34: 32 | P34: Work orders given 28 | In re-tendering 4 (all PHSC). 8 each across IT/Mandi/Panch Raj/PHSC.
C35: AAC Ph 8/9/10 — inaugurated | D35: sites | E35: 48 | F35: 48 | H35: 17 | I35: =IF(AND(ISNUMBER(G35),ISNUMBER(H35)),H35-G35,"") | J35: =IF(AND(ISNUMBER(E35),E35>0,ISNUMBER(H35)),H35/E35,"") -> 0.35416667 | K35: Completed | L35: =IF(M35="Yes","🔴 BOTTOM",IF(M35="No","✓ Cleared",IF(Q35="MIN",IF(AND(ISNUMBER(F35),ISNUMBER(H35)),IF(H35<F35*'Master Dashboard'!$B$4,"🔴 LOW",""),""),IF(Q35="MAX",IF(AND(ISNUMBER(F35),ISNUMBER(H35)),IF(H35>F35,"🔴 HIGH",""),""),"")))) -> 🔴 LOW | M35: Auto | N35: Gov Cell (report) | O35: 05-06-2026 | P35: of 48 total | Q35: MIN | R35: ADCG-035
C36: AAC Ph 8/9/10 — work in progress | D36: sites | H36: 30 | I36: =IF(AND(ISNUMBER(G36),ISNUMBER(H36)),H36-G36,"") | J36: =IF(AND(ISNUMBER(E36),E36>0,ISNUMBER(H36)),H36/E36,"") | K36: In Progress | L36: =IF(M36="Yes","🔴 BOTTOM",IF(M36="No","✓ Cleared",IF(Q36="MIN",IF(AND(ISNUMBER(F36),ISNUMBER(H36)),IF(H36<F36*'Master Dashboard'!$B$4,"🔴 LOW",""),""),IF(Q36="MAX",IF(AND(ISNUMBER(F36),ISNUMBER(H36)),IF(H36>F36,"🔴 HIGH",""),""),"")))) | M36: Auto | N36: Gov Cell (report) | O36: 05-06-2026 | R36: ADCG-036
C37: AAC — at >=95% completion | D37: sites | H37: 10 | I37: =IF(AND(ISNUMBER(G37),ISNUMBER(H37)),H37-G37,"") | J37: =IF(AND(ISNUMBER(E37),E37>0,ISNUMBER(H37)),H37/E37,"") | K37: In Progress | L37: =IF(M37="Yes","🔴 BOTTOM",IF(M37="No","✓ Cleared",IF(Q37="MIN",IF(AND(ISNUMBER(F37),ISNUMBER(H37)),IF(H37<F37*'Master Dashboard'!$B$4,"🔴 LOW",""),""),IF(Q37="MAX",IF(AND(ISNUMBER(F37),ISNUMBER(H37)),IF(H37>F37,"🔴 HIGH",""),""),"")))) | M37: Auto | N37: Gov Cell (report) | O37: 05-06-2026 | R37: ADCG-037
C38: AAC — at 90% completion | D38: sites | H38: 2 | I38: =IF(AND(ISNUMBER(G38),ISNUMBER(H38)),H38-G38,"") | J38: =IF(AND(ISNUMBER(E38),E38>0,ISNUMBER(H38)),H38/E38,"") | K38: In Progress | L38: =IF(M38="Yes","🔴 BOTTOM",IF(M38="No","✓ Cleared",IF(Q38="MIN",IF(AND(ISNUMBER(F38),ISNUMBER(H38)),IF(H38<F38*'Master Dashboard'!$B$4,"🔴 LOW",""),""),IF(Q38="MAX",IF(AND(ISNUMBER(F38),ISNUMBER(H38)),IF(H38>F38,"🔴 HIGH",""),""),"")))) | M38: Auto | N38: Gov Cell (report) | O38: 05-06-2026 | R38: ADCG-038
C39: AAC — at 80% completion | D39: sites | H39: 4 | I39: =IF(AND(ISNUMBER(G39),ISNUMBER(H39)),H39-G39,"") | J39: =IF(AND(ISNUMBER(E39),E39>0,ISNUMBER(H39)),H39/E39,"") | K39: In Progress | L39: =IF(M39="Yes","🔴 BOTTOM",IF(M39="No","✓ Cleared",IF(Q39="MIN",IF(AND(ISNUMBER(F39),ISNUMBER(H39)),IF(H39<F39*'Master Dashboard'!$B$4,"🔴 LOW",""),""),IF(Q39="MAX",IF(AND(ISNUMBER(F39),ISNUMBER(H39)),IF(H39>F39,"🔴 HIGH",""),""),"")))) | M39: Auto | N39: Gov Cell (report) | O39: 05-06-2026 | R39: ADCG-039
C40: AAC — at 70% completion | D40: sites | H40: 7 | I40: =IF(AND(ISNUMBER(G40),ISNUMBER(H40)),H40-G40,"") | J40: =IF(AND(ISNUMBER(E40),E40>0,ISNUMBER(H40)),H40/E40,"") | K40: In Progress | L40: =IF(M40="Yes","🔴 BOTTOM",IF(M40="No","✓ Cleared",IF(Q40="MIN",IF(AND(ISNUMBER(F40),ISNUMBER(H40)),IF(H40<F40*'Master Dashboard'!$B$4,"🔴 LOW",""),""),IF(Q40="MAX",IF(AND(ISNUMBER(F40),ISNUMBER(H40)),IF(H40>F40,"🔴 HIGH",""),""),"")))) | M40: Auto | N40: Gov Cell (report) | O40: 05-06-2026 | R40: ADCG-040
C41: AAC — at 60% completion | D41: sites | H41: 6 | I41: =IF(AND(ISNUMBER(G41),ISNUMBER(H41)),H41-G41,"") | J41: =IF(AND(ISNUMBER(E41),E41>0,ISNUMBER(H41)),H41/E41,"") | K41: In Progress | L41: =IF(M41="Yes","🔴 BOTTOM",IF(M41="No","✓ Cleared",IF(Q41="MIN",IF(AND(ISNUMBER(F41),ISNUMBER(H41)),IF(H41<F41*'Master Dashboard'!$B$4,"🔴 LOW",""),""),IF(Q41="MAX",IF(AND(ISNUMBER(F41),ISNUMBER(H41)),IF(H41>F41,"🔴 HIGH",""),""),"")))) | M41: Auto | N41: Gov Cell (report) | O41: 05-06-2026 | R41: ADCG-041
C42: AAC — problematic site | D42: sites | E42: 0 | F42: 0 | H42: 1 | I42: =IF(AND(ISNUMBER(G42),ISNUMBER(H42)),H42-G42,"") | J42: =IF(AND(ISNUMBER(E42),E42>0,ISNUMBER(H42)),H42/E42,"") | K42: Pending/Blocked | L42: =IF(M42="Yes","🔴 BOTTOM",IF(M42="No","✓ Cleared",IF(Q42="MIN",IF(AND(ISNUMBER(F42),ISNUMBER(H42)),IF(H42<F42*'Master Dashboard'!$B$4,"🔴 LOW",""),""),IF(Q42="MAX",IF(AND(ISNUMBER(F42),ISNUMBER(H42)),IF(H42>F42,"🔴 HIGH",""),""),"")))) -> 🔴 HIGH | M42: Auto | N42: Gov Cell (report) | O42: 05-06-2026 | Q42: MAX | R42: ADCG-042
...

Sheet ADC (RD)
A1: ADC (RD) — Priority Agenda Review | DC Ludhiana (MASTER)
A2: Sr | B2: Priority Agenda | C2: KPI / Metric | D2: Concerned Officer / Unit | E2: Target / Total | F2: Flag Bar | G2: Last Value | H2: Current Value | I2: Change | J2: Achieved % | K2: Status | L2: Auto-Flag | M2: Bottom Performer | N2: Updated By | O2: Update Date | P2: Remarks / Context / Pending Action | Q2: Rule | R2: Key
A3: ▣ SCHEMES — metric-based (fed from officer workbook)
A4: 1 | B4: Mavan Dhiyan Satikar Yojana (MMMDSY) | C4: 📊 Mahila Satkar Sakhis registered | H4: 14548 | P4: of 25,556 target (56.92%, was 55.29%). Remaining 11,008.
C5: 📊 Anganwadi readiness | H5: Paint 72.8% | Furniture 100% | P5: Paintwork 1,810/2,487; chairs/tables/printing 100%. Nodals: BDPO 6/12, MCL 2/14.
C6: Mahila Satkar Sakhis — registered | D6: sakhis | E6: 25556 | F6: 20445 | G6: 14107 | H6: 14548 | I6: =IF(AND(ISNUMBER(G6),ISNUMBER(H6)),H6-G6,"") -> 441 | J6: =IF(AND(ISNUMBER(E6),E6>0,ISNUMBER(H6)),H6/E6,"") -> 0.56925967 | K6: In Progress | L6: =IF(M6="Yes","🔴 BOTTOM",IF(M6="No","✓ Cleared",IF(Q6="MIN",IF(AND(ISNUMBER(F6),ISNUMBER(H6)),IF(H6<F6*'Master Dashboard'!$B$4,"🔴 LOW",""),""),IF(Q6="MAX",IF(AND(ISNUMBER(F6),ISNUMBER(H6)),IF(H6>F6,"🔴 HIGH",""),""),"")))) -> 🔴 LOW | M6: Auto | N6: Gov Cell (report) | O6: 05-06-2026 | P6: Remaining 11,008 | 56.92% (was 55.29%) | Q6: MIN | R6: ADCRD-001
C7: Anganwadi Centres — paintwork done | D7: centres | E7: 2487 | F7: 2238 | G7: 1776 | H7: 1810 | I7: =IF(AND(ISNUMBER(G7),ISNUMBER(H7)),H7-G7,"") -> 34 | J7: =IF(AND(ISNUMBER(E7),E7>0,ISNUMBER(H7)),H7/E7,"") -> 0.72778448 | K7: In Progress | L7: =IF(M7="Yes","🔴 BOTTOM",IF(M7="No","✓ Cleared",IF(Q7="MIN",IF(AND(ISNUMBER(F7),ISNUMBER(H7)),IF(H7<F7*'Master Dashboard'!$B$4,"🔴 LOW",""),""),IF(Q7="MAX",IF(AND(ISNUMBER(F7),ISNUMBER(H7)),IF(H7>F7,"🔴 HIGH",""),""),"")))) -> 🔴 LOW | M7: Auto | N7: Gov Cell (report) | O7: 05-06-2026 | P7: Remaining 677 | 72.77% (was 71.4%) | Q7: MIN | R7: ADCRD-002
C8: Anganwadi Centres — chairs supplied | D8: centres | E8: 2487 | F8: 2487 | G8: 2487 | H8: 2487 | I8: =IF(AND(ISNUMBER(G8),ISNUMBER(H8)),H8-G8,"") -> 0 | J8: =IF(AND(ISNUMBER(E8),E8>0,ISNUMBER(H8)),H8/E8,"") -> 1 | K8: Completed | L8: =IF(M8="Yes","🔴 BOTTOM",IF(M8="No","✓ Cleared",IF(Q8="MIN",IF(AND(ISNUMBER(F8),ISNUMBER(H8)),IF(H8<F8*'Master Dashboard'!$B$4,"🔴 LOW",""),""),IF(Q8="MAX",IF(AND(ISNUMBER(F8),ISNUMBER(H8)),IF(H8>F8,"🔴 HIGH",""),""),"")))) | M8: Auto | N8: Gov Cell (report) | O8: 05-06-2026 | P8: 100% | Q8: MIN | R8: ADCRD-003
C9: Anganwadi Centres — tables supplied | D9: centres | E9: 2487 | F9: 2487 | G9: 2487 | H9: 2487 | I9: =IF(AND(ISNUMBER(G9),ISNUMBER(H9)),H9-G9,"") -> 0 | J9: =IF(AND(ISNUMBER(E9),E9>0,ISNUMBER(H9)),H9/E9,"") -> 1 | K9: Completed | L9: =IF(M9="Yes","🔴 BOTTOM",IF(M9="No","✓ Cleared",IF(Q9="MIN",IF(AND(ISNUMBER(F9),ISNUMBER(H9)),IF(H9<F9*'Master Dashboard'!$B$4,"🔴 LOW",""),""),IF(Q9="MAX",IF(AND(ISNUMBER(F9),ISNUMBER(H9)),IF(H9>F9,"🔴 HIGH",""),""),"")))) | M9: Auto | N9: Gov Cell (report) | O9: 05-06-2026 | P9: 100% | Q9: MIN | R9: ADCRD-004
C10: Anganwadi Centres — printing material | D10: centres | E10: 2487 | F10: 2487 | G10: 2487 | H10: 2487 | I10: =IF(AND(ISNUMBER(G10),ISNUMBER(H10)),H10-G10,"") -> 0 | J10: =IF(AND(ISNUMBER(E10),E10>0,ISNUMBER(H10)),H10/E10,"") -> 1 | K10: Completed | L10: =IF(M10="Yes","🔴 BOTTOM",IF(M10="No","✓ Cleared",IF(Q10="MIN",IF(AND(ISNUMBER(F10),ISNUMBER(H10)),IF(H10<F10*'Master Dashboard'!$B$4,"🔴 LOW",""),""),IF(Q10="MAX",IF(AND(ISNUMBER(F10),ISNUMBER(H10)),IF(H10>F10,"🔴 HIGH",""),""),"")))) | M10: Auto | N10: Gov Cell (report) | O10: 05-06-2026 | P10: 100% | Q10: MIN | R10: ADCRD-005
C11: BDPO Nodals appointed | D11: nodals | E11: 12 | F11: 12 | G11: 0 | H11: 6 | I11: =IF(AND(ISNUMBER(G11),ISNUMBER(H11)),H11-G11,"") -> 6 | J11: =IF(AND(ISNUMBER(E11),E11>0,ISNUMBER(H11)),H11/E11,"") -> 0.5 | K11: In Progress | L11: =IF(M11="Yes","🔴 BOTTOM",IF(M11="No","✓ Cleared",IF(Q11="MIN",IF(AND(ISNUMBER(F11),ISNUMBER(H11)),IF(H11<F11*'Master Dashboard'!$B$4,"🔴 LOW",""),""),IF(Q11="MAX",IF(AND(ISNUMBER(F11),ISNUMBER(H11)),IF(H11>F11,"🔴 HIGH",""),""),"")))) -> 🔴 LOW | M11: Auto | N11: Gov Cell (report) | O11: 05-06-2026 | P11: 50% (was 0%) | Q11: MIN | R11: ADCRD-006
C12: MCL Nodals appointed | D12: nodals | E12: 14 | F12: 14 | G12: 2 | H12: 2 | I12: =IF(AND(ISNUMBER(G12),ISNUMBER(H12)),H12-G12,"") -> 0 | J12: =IF(AND(ISNUMBER(E12),E12>0,ISNUMBER(H12)),H12/E12,"") -> 0.14285714 | K12: Pending/Blocked | L12: =IF(M12="Yes","🔴 BOTTOM",IF(M12="No","✓ Cleared",IF(Q12="MIN",IF(AND(ISNUMBER(F12),ISNUMBER(H12)),IF(H12<F12*'Master Dashboard'!$B$4,"🔴 LOW",""),""),IF(Q12="MAX",IF(AND(ISNUMBER(F12),ISNUMBER(H12)),IF(H12>F12,"🔴 HIGH",""),""),"")))) -> 🔴 LOW | M12: Auto | N12: Gov Cell (report) | O12: 05-06-2026 | P12: 14.2% — stalled | Q12: MIN | R12: ADCRD-007
A13: 2 | B13: Rangla Punjab — Phase I | C13: 📊 Total works proposed | H13: 433 | P13: District total, Phase I. Sanctioned amount Rs 34.99 Cr.
C14: 📊 Works started | H14: 431 | P14: 431 of 433 started (Total − Not started).
C15: 📊 Works in progress | H15: 326 | P15: Currently under execution.
C16: 📊 Works completed | H16: 105 | P16: Physically complete.
C17: 📊 Works NOT started | H17: 2 | P17: DD Animal Husbandry (1) + XEN Prov. Divn B&R (1).
C18: Phase I — works completed (district) | D18: works | E18: 433 | F18: 433 | H18: 105 | I18: =IF(AND(ISNUMBER(G18),ISNUMBER(H18)),H18-G18,"") | J18: =IF(AND(ISNUMBER(E18),E18>0,ISNUMBER(H18)),H18/E18,"") -> 0.24249423 | K18: In Progress | L18: =IF(M18="Yes","🔴 BOTTOM",IF(M18="No","✓ Cleared",IF(Q18="MIN",IF(AND(ISNUMBER(F18),ISNUMBER(H18)),IF(H18<F18*'Master Dashboard'!$B$4,"🔴 LOW",""),""),IF(Q18="MAX",IF(AND(ISNUMBER(F18),ISNUMBER(H18)),IF(H18>F18,"🔴 HIGH",""),""),"")))) -> 🔴 LOW | M18: Auto | N18: Gov Cell (report) | O18: 05-06-2026 | P18: 326 in progress; 2 not started | Q18: MIN | R18: ADCRD-008
C19: P-I completed — BDPO Doraha | D19: works | E19: 34 | F19: 1 | H19: 29 | I19: =IF(AND(ISNUMBER(G19),ISNUMBER(H19)),H19-G19,"") | J19: =IF(AND(ISNUMBER(E19),E19>0,ISNUMBER(H19)),H19/E19,"") -> 0.85294118 | K19: In Progress | L19: =IF(M19="Yes","🔴 BOTTOM",IF(M19="No","✓ Cleared",IF(Q19="MIN",IF(AND(ISNUMBER(F19),ISNUMBER(H19)),IF(H19<F19*'Master Dashboard'!$B$4,"🔴 LOW",""),""),IF(Q19="MAX",IF(AND(ISNUMBER(F19),ISNUMBER(H19)),IF(H19>F19,"🔴 HIGH",""),""),"")))) | M19: Auto | N19: Gov Cell (report) | O19: 05-06-2026 | P19: of 34 proposed — Phase-I works physically completed by this agency of its proposed total. | Q19: MIN | R19: ADCRD-009
C20: P-I completed — BDPO Jagraon | D20: works | E20: 42 | F20: 1 | H20: 4 | I20: =IF(AND(ISNUMBER(G20),ISNUMBER(H20)),H20-G20,"") | J20: =IF(AND(ISNUMBER(E20),E20>0,ISNUMBER(H20)),H20/E20,"") -> 0.095238095 | K20: In Progress | L20: =IF(M20="Yes","🔴 BOTTOM",IF(M20="No","✓ Cleared",IF(Q20="MIN",IF(AND(ISNUMBER(F20),ISNUMBER(H20)),IF(H20<F20*'Master Dashboard'!$B$4,"🔴 LOW",""),""),IF(Q20="MAX",IF(AND(ISNUMBER(F20),ISNUMBER(H20)),IF(H20>F20,"🔴 HIGH",""),""),"")))) | M20: Auto | N20: Gov Cell (report) | O20: 05-06-2026 | P20: of 42 proposed — Phase-I works physically completed by this agency of its proposed total. | Q20: MIN | R20: ADCRD-010
C21: P-I completed — BDPO Khanna | D21: works | E21: 26 | F21: 1 | H21: 0 | I21: =IF(AND(ISNUMBER(G21),ISNUMBER(H21)),H21-G21,"") | J21: =IF(AND(ISNUMBER(E21),E21>0,ISNUMBER(H21)),H21/E21,"") -> 0 | K21: In Progress | L21: =IF(M21="Yes","🔴 BOTTOM",IF(M21="No","✓ Cleared",IF(Q21="MIN",IF(AND(ISNUMBER(F21),ISNUMBER(H21)),IF(H21<F21*'Master Dashboard'!$B$4,"🔴 LOW",""),""),IF(Q21="MAX",IF(AND(ISNUMBER(F21),ISNUMBER(H21)),IF(H21>F21,"🔴 HIGH",""),""),"")))) -> 🔴 LOW | M21: Auto | N21: Gov Cell (report) | O21: 05-06-2026 | P21: of 26 proposed — Phase-I works physically completed by this agency of its proposed total. | Q21: MIN | R21: ADCRD-011
C22: P-I completed — BDPO Ludhiana One | D22: works | E22: 76 | F22: 1 | H22: 0 | I22: =IF(AND(ISNUMBER(G22),ISNUMBER(H22)),H22-G22,"") | J22: =IF(AND(ISNUMBER(E22),E22>0,ISNUMBER(H22)),H22/E22,"") -> 0 | K22: In Progress | L22: =IF(M22="Yes","🔴 BOTTOM",IF(M22="No","✓ Cleared",IF(Q22="MIN",IF(AND(ISNUMBER(F22),ISNUMBER(H22)),IF(H22<F22*'Master Dashboard'!$B$4,"🔴 LOW",""),""),IF(Q22="MAX",IF(AND(ISNUMBER(F22),ISNUMBER(H22)),IF(H22>F22,"🔴 HIGH",""),""),"")))) -> 🔴 LOW | M22: Auto | N22: Gov Cell (report) | O22: 05-06-2026 | P22: of 76 proposed — Phase-I works physically completed by this agency of its proposed total. | Q22: MIN | R22: ADCRD-012
C23: P-I completed — BDPO Ludhiana Two | D23: works | E23: 48 | F23: 1 | H23: 1 | I23: =IF(AND(ISNUMBER(G23),ISNUMBER(H23)),H23-G23,"") | J23: =IF(AND(ISNUMBER(E23),E23>0,ISNUMBER(H23)),H23/E23,"") -> 0.020833333 | K23: In Progress | L23: =IF(M23="Yes","🔴 BOTTOM",IF(M23="No","✓ Cleared",IF(Q23="MIN",IF(AND(ISNUMBER(F23),ISNUMBER(H23)),IF(H23<F23*'Master Dashboard'!$B$4,"🔴 LOW",""),""),IF(Q23="MAX",IF(AND(ISNUMBER(F23),ISNUMBER(H23)),IF(H23>F23,"🔴 HIGH",""),""),"")))) | M23: Auto | N23: Gov Cell (report) | O23: 05-06-2026 | P23: of 48 proposed — Phase-I works physically completed by this agency of its proposed total. | Q23: MIN | R23: ADCRD-013
C24: P-I completed — BDPO Maloud | D24: works | E24: 33 | F24: 1 | H24: 19 | I24: =IF(AND(ISNUMBER(G24),ISNUMBER(H24)),H24-G24,"") | J24: =IF(AND(ISNUMBER(E24),E24>0,ISNUMBER(H24)),H24/E24,"") -> 0.57575758 | K24: In Progress | L24: =IF(M24="Yes","🔴 BOTTOM",IF(M24="No","✓ Cleared",IF(Q24="MIN",IF(AND(ISNUMBER(F24),ISNUMBER(H24)),IF(H24<F24*'Master Dashboard'!$B$4,"🔴 LOW",""),""),IF(Q24="MAX",IF(AND(ISNUMBER(F24),ISNUMBER(H24)),IF(H24>F24,"🔴 HIGH",""),""),"")))) | M24: Auto | N24: Gov Cell (report) | O24: 05-06-2026 | P24: of 33 proposed — Phase-I works physically completed by this agency of its proposed total. | Q24: MIN | R24: ADCRD-014
C25: P-I completed — BDPO Raikot | D25: works | E25: 21 | F25: 1 | H25: 21 | I25: =IF(AND(ISNUMBER(G25),ISNUMBER(H25)),H25-G25,"") | J25: =IF(AND(ISNUMBER(E25),E25>0,ISNUMBER(H25)),H25/E25,"") -> 1 | K25: In Progress | L25: =IF(M25="Yes","🔴 BOTTOM",IF(M25="No","✓ Cleared",IF(Q25="MIN",IF(AND(ISNUMBER(F25),ISNUMBER(H25)),IF(H25<F25*'Master Dashboard'!$B$4,"🔴 LOW",""),""),IF(Q25="MAX",IF(AND(ISNUMBER(F25),ISNUMBER(H25)),IF(H25>F25,"🔴 HIGH",""),""),"")))) | M25: Auto | N25: Gov Cell (report) | O25: 05-06-2026 | P25: of 21 proposed — Phase-I works physically completed by this agency of its proposed total. | Q25: MIN | R25: ADCRD-015
C26: P-I completed — BDPO Samrala | D26: works | E26: 34 | F26: 1 | H26: 17 | I26: =IF(AND(ISNUMBER(G26),ISNUMBER(H26)),H26-G26,"") | J26: =IF(AND(ISNUMBER(E26),E26>0,ISNUMBER(H26)),H26/E26,"") -> 0.5 | K26: In Progress | L26: =IF(M26="Yes","🔴 BOTTOM",IF(M26="No","✓ Cleared",IF(Q26="MIN",IF(AND(ISNUMBER(F26),ISNUMBER(H26)),IF(H26<F26*'Master Dashboard'!$B$4,"🔴 LOW",""),""),IF(Q26="MAX",IF(AND(ISNUMBER(F26),ISNUMBER(H26)),IF(H26>F26,"🔴 HIGH",""),""),"")))) | M26: Auto | N26: Gov Cell (report) | O26: 05-06-2026 | P26: of 34 proposed — Phase-I works physically completed by this agency of its proposed total. | Q26: MIN | R26: ADCRD-016
C27: P-I completed — BDPO Sidhwan Bet | D27: works | E27: 24 | F27: 1 | H27: 10 | I27: =IF(AND(ISNUMBER(G27),ISNUMBER(H27)),H27-G27,"") | J27: =IF(AND(ISNUMBER(E27),E27>0,ISNUMBER(H27)),H27/E27,"") -> 0.41666667 | K27: In Progress | L27: =IF(M27="Yes","🔴 BOTTOM",IF(M27="No","✓ Cleared",IF(Q27="MIN",IF(AND(ISNUMBER(F27),ISNUMBER(H27)),IF(H27<F27*'Master Dashboard'!$B$4,"🔴 LOW",""),""),IF(Q27="MAX",IF(AND(ISNUMBER(F27),ISNUMBER(H27)),IF(H27>F27,"🔴 HIGH",""),""),"")))) | M27: Auto | N27: Gov Cell (report) | O27: 05-06-2026 | P27: of 24 proposed — Phase-I works physically completed by this agency of its proposed total. | Q27: MIN | R27: ADCRD-017
C28: P-I completed — BDPO Sudhar | D28: works | E28: 27 | F28: 1 | H28: 0 | I28: =IF(AND(ISNUMBER(G28),ISNUMBER(H28)),H28-G28,"") | J28: =IF(AND(ISNUMBER(E28),E28>0,ISNUMBER(H28)),H28/E28,"") -> 0 | K28: In Progress | L28: =IF(M28="Yes","🔴 BOTTOM",IF(M28="No","✓ Cleared",IF(Q28="MIN",IF(AND(ISNUMBER(F28),ISNUMBER(H28)),IF(H28<F28*'Master Dashboard'!$B$4,"🔴 LOW",""),""),IF(Q28="MAX",IF(AND(ISNUMBER(F28),ISNUMBER(H28)),IF(H28>F28,"🔴 HIGH",""),""),"")))) -> 🔴 LOW | M28: Auto | N28: Gov Cell (report) | O28: 05-06-2026 | P28: of 27 proposed — Phase-I works physically completed by this agency of its proposed total. | Q28: MIN | R28: ADCRD-018
C29: P-I completed — BDPO Pakhowal | D29: works | E29: 13 | F29: 1 | H29: 1 | I29: =IF(AND(ISNUMBER(G29),ISNUMBER(H29)),H29-G29,"") | J29: =IF(AND(ISNUMBER(E29),E29>0,ISNUMBER(H29)),H29/E29,"") -> 0.076923077 | K29: In Progress | L29: =IF(M29="Yes","🔴 BOTTOM",IF(M29="No","✓ Cleared",IF(Q29="MIN",IF(AND(ISNUMBER(F29),ISNUMBER(H29)),IF(H29<F29*'Master Dashboard'!$B$4,"🔴 LOW",""),""),IF(Q29="MAX",IF(AND(ISNUMBER(F29),ISNUMBER(H29)),IF(H29>F29,"🔴 HIGH",""),""),"")))) | M29: Auto | N29: Gov Cell (report) | O29: 05-06-2026 | P29: of 13 proposed — Phase-I works physically completed by this agency of its proposed total. | Q29: MIN | R29: ADCRD-019
C30: P-I completed — MCL | D30: works | E30: 39 | F30: 1 | H30: 0 | I30: =IF(AND(ISNUMBER(G30),ISNUMBER(H30)),H30-G30,"") | J30: =IF(AND(ISNUMBER(E30),E30>0,ISNUMBER(H30)),H30/E30,"") -> 0 | K30: In Progress | L30: =IF(M30="Yes","🔴 BOTTOM",IF(M30="No","✓ Cleared",IF(Q30="MIN",IF(AND(ISNUMBER(F30),ISNUMBER(H30)),IF(H30<F30*'Master Dashboard'!$B$4,"🔴 LOW",""),""),IF(Q30="MAX",IF(AND(ISNUMBER(F30),ISNUMBER(H30)),IF(H30>F30,"🔴 HIGH",""),""),"")))) -> 🔴 LOW | M30: Auto | N30: Gov Cell (report) | O30: 05-06-2026 | P30: of 39 proposed — Phase-I works physically completed by this agency of its proposed total. | Q30: MIN | R30: ADCRD-020
A31: 3 | B31: Rangla Punjab — Phase II | C31: 📊 Total works proposed | H31: 400 | P31: District total, Phase II. Sanctioned amount Rs 31.79 Cr.
C32: 📊 Works started | H32: 90 | P32: 90 of 400 started (Total − Not started).
C33: 📊 Works in progress | H33: 79 | P33: Currently under execution.
C34: 📊 Works completed | H34: 11 | P34: Physically complete.
C35: 📊 Works NOT started | H35: 310 | P35: All to begin by 5 June. Largest: MCL 73, Jagraon 43, Dehlon 30, Khanna 28.
C36: Phase II — works completed (district) | D36: works | E36: 400 | F36: 400 | H36: 11 | I36: =IF(AND(ISNUMBER(G36),ISNUMBER(H36)),H36-G36,"") | J36: =IF(AND(ISNUMBER(E36),E36>0,ISNUMBER(H36)),H36/E36,"") -> 0.0275 | K36: Pending/Blocked | L36: =IF(M36="Yes","🔴 BOTTOM",IF(M36="No","✓ Cleared",IF(Q36="MIN",IF(AND(ISNUMBER(F36),ISNUMBER(H36)),IF(H36<F36*'Master Dashboard'!$B$4,"🔴 LOW",""),""),IF(Q36="MAX",IF(AND(ISNUMBER(F36),ISNUMBER(H36)),IF(H36>F36,"🔴 HIGH",""),""),"")))) -> 🔴 LOW | M36: Auto | N36: Gov Cell (report) | O36: 05-06-2026 | P36: 79 in progress; 310 NOT started | Q36: MIN | R36: ADCRD-021
C37: Phase II — works NOT started (district) | D37: works | E37: 0 | F37: 0 | H37: 310 | I37: =IF(AND(ISNUMBER(G37),ISNUMBER(H37)),H37-G37,"") | J37: =IF(AND(ISNUMBER(E37),E37>0,ISNUMBER(H37)),H37/E37,"") | K37: Pending/Blocked | L37: =IF(M37="Yes","🔴 BOTTOM",IF(M37="No","✓ Cleared",IF(Q37="MIN",IF(AND(ISNUMBER(F37),ISNUMBER(H37)),IF(H37<F37*'Master Dashboard'!$B$4,"🔴 LOW",""),""),IF(Q37="MAX",IF(AND(ISNUMBER(F37),ISNUMBER(H37)),IF(H37>F37,"🔴 HIGH",""),""),"")))) -> 🔴 HIGH | M37: Auto | N37: Gov Cell (report) | O37: 05-06-2026 | P37: To start by 5 Jun | Q37: MAX | R37: ADCRD-022
C38: P-II not started — MCL | D38: works | E38: 0 | F38: 20 | H38: 73 | I38: =IF(AND(ISNUMBER(G38),ISNUMBER(H38)),H38-G38,"") | J38: =IF(AND(ISNUMBER(E38),E38>0,ISNUMBER(H38)),H38/E38,"") | K38: Pending/Blocked | L38: =IF(M38="Yes","🔴 BOTTOM",IF(M38="No","✓ Cleared",IF(Q38="MIN",IF(AND(ISNUMBER(F38),ISNUMBER(H38)),IF(H38<F38*'Master Dashboard'!$B$4,"🔴 LOW",""),""),IF(Q38="MAX",IF(AND(ISNUMBER(F38),ISNUMBER(H38)),IF(H38>F38,"🔴 HIGH",""),""),"")))) -> 🔴 HIGH | M38: Auto | N38: Gov Cell (report) | O38: 05-06-2026 | P38: of 73 proposed — Phase-II works not yet started by this agency of its proposed total. | Q38: MAX | R38: ADCRD-023
C39: P-II not started — BDPO Jagraon | D39: works | E39: 0 | F39: 20 | H39: 43 | I39: =IF(AND(ISNUMBER(G39),ISNUMBER(H39)),H39-G39,"") | J39: =IF(AND(ISNUMBER(E39),E39>0,ISNUMBER(H39)),H39/E39,"") | K39: Pending/Blocked | L39: =IF(M39="Yes","🔴 BOTTOM",IF(M39="No","✓ Cleared",IF(Q39="MIN",IF(AND(ISNUMBER(F39),ISNUMBER(H39)),IF(H39<F39*'Master Dashboard'!$B$4,"🔴 LOW",""),""),IF(Q39="MAX",IF(AND(ISNUMBER(F39),ISNUMBER(H39)),IF(H39>F39,"🔴 HIGH",""),""),"")))) -> 🔴 HIGH | M39: Auto | N39: Gov Cell (report) | O39: 05-06-2026 | P39: of 44 proposed — Phase-II works not yet started by this agency of its proposed total. | Q39: MAX | R39: ADCRD-024
C40: P-II not started — BDPO Khanna | D40: works | E40: 0 | F40: 20 | H40: 28 | I40: =IF(AND(ISNUMBER(G40),ISNUMBER(H40)),H40-G40,"") | J40: =IF(AND(ISNUMBER(E40),E40>0,ISNUMBER(H40)),H40/E40,"") | K40: Pending/Blocked | L40: =IF(M40="Yes","🔴 BOTTOM",IF(M40="No","✓ Cleared",IF(Q40="MIN",IF(AND(ISNUMBER(F40),ISNUMBER(H40)),IF(H40<F40*'Master Dashboard'!$B$4,"🔴 LOW",""),""),IF(Q40="MAX",IF(AND(ISNUMBER(F40),ISNUMBER(H40)),IF(H40>F40,"🔴 HIGH",""),""),"")))) -> 🔴 HIGH | M40: Auto | N40: Gov Cell (report) | O40: 05-06-2026 | P40: of 28 proposed — Phase-II works not yet started by this agency of its proposed total. | Q40: MAX | R40: ADCRD-025
...

Sheet ADC (UD)
A1: ADC (UD) — Priority Agenda Review | DC Ludhiana (MASTER)
A2: Sr | B2: Priority Agenda | C2: KPI / Metric | D2: Concerned Officer / Unit | E2: Target / Total | F2: Flag Bar | G2: Last Value | H2: Current Value | I2: Change | J2: Achieved % | K2: Status | L2: Auto-Flag | M2: Bottom Performer | N2: Updated By | O2: Update Date | P2: Remarks / Context / Pending Action | Q2: Rule | R2: Key
A3: ▣ PRIORITY TASKS — qualitative / assigned tasks
A4: 1 | B4: MM Tirath Yatra Yojana | C4: Bills pending (count) | D4: bills | H4: 0 | I4: =IF(AND(ISNUMBER(G4),ISNUMBER(H4)),H4-G4,"") | J4: =IF(AND(ISNUMBER(E4),E4>0,ISNUMBER(H4)),H4/E4,"") | K4: In Progress | L4: =IF(M4="Yes","🔴 BOTTOM",IF(M4="No","✓ Cleared",IF(Q4="MIN",IF(AND(ISNUMBER(F4),ISNUMBER(H4)),IF(H4<F4*'Master Dashboard'!$B$4,"🔴 LOW",""),""),IF(Q4="MAX",IF(AND(ISNUMBER(F4),ISNUMBER(H4)),IF(H4>F4,"🔴 HIGH",""),""),"")))) | M4: Auto | N4: Gov Cell (report) | O4: 05-06-2026 | P4: Cleared till 04 May 2026; none pending | R4: ADCUD-001
C5: All bills up to date cleared? (Y/N) | D5: Y/N | I5: =IF(AND(ISNUMBER(G5),ISNUMBER(H5)),H5-G5,"") | J5: =IF(AND(ISNUMBER(E5),E5>0,ISNUMBER(H5)),H5/E5,"") | K5: In Progress | L5: =IF(M5="Yes","🔴 BOTTOM",IF(M5="No","✓ Cleared",IF(Q5="MIN",IF(AND(ISNUMBER(F5),ISNUMBER(H5)),IF(H5<F5*'Master Dashboard'!$B$4,"🔴 LOW",""),""),IF(Q5="MAX",IF(AND(ISNUMBER(F5),ISNUMBER(H5)),IF(H5>F5,"🔴 HIGH",""),""),"")))) | M5: Auto | R5: ADCUD-002
A6: 2 | B6: Buddha Dariya — NGT / Dairies / CBG | C6: Dairies identified (Rajpur/Haibowal) | D6: no. | H6: 6 | I6: =IF(AND(ISNUMBER(G6),ISNUMBER(H6)),H6-G6,"") | J6: =IF(AND(ISNUMBER(E6),E6>0,ISNUMBER(H6)),H6/E6,"") | K6: In Progress | M6: Auto | N6: Gov Cell (report) | O6: 05-06-2026 | P6: Disconnection done; MCL direction passed | R6: ADCUD-003
C7: Tajpur — dairies disconnected | D7: no. | E7: 21 | F7: 21 | H7: 16 | I7: =IF(AND(ISNUMBER(G7),ISNUMBER(H7)),H7-G7,"") | J7: =IF(AND(ISNUMBER(E7),E7>0,ISNUMBER(H7)),H7/E7,"") -> 0.76190476 | K7: In Progress | L7: =IF(M7="Yes","🔴 BOTTOM",IF(M7="No","✓ Cleared",IF(Q7="MIN",IF(AND(ISNUMBER(F7),ISNUMBER(H7)),IF(H7<F7*'Master Dashboard'!$B$4,"🔴 LOW",""),""),IF(Q7="MAX",IF(AND(ISNUMBER(F7),ISNUMBER(H7)),IF(H7>F7,"🔴 HIGH",""),""),"")))) -> 🔴 LOW | M7: Auto | N7: Gov Cell (report) | O7: 05-06-2026 | P7: 21 dairies out of complex | Q7: MIN | R7: ADCUD-004
C8: CBG plant — site identified? (Y/N) | D8: Y/N | I8: =IF(AND(ISNUMBER(G8),ISNUMBER(H8)),H8-G8,"") | J8: =IF(AND(ISNUMBER(E8),E8>0,ISNUMBER(H8)),H8/E8,"") | K8: Pending/Blocked | L8: =IF(M8="Yes","🔴 BOTTOM",IF(M8="No","✓ Cleared",IF(Q8="MIN",IF(AND(ISNUMBER(F8),ISNUMBER(H8)),IF(H8<F8*'Master Dashboard'!$B$4,"🔴 LOW",""),""),IF(Q8="MAX",IF(AND(ISNUMBER(F8),ISNUMBER(H8)),IF(H8>F8,"🔴 HIGH",""),""),"")))) | M8: Auto | P8: Jamalpur dump site found for carcass | R8: ADCUD-005
C9: CETP/STP — ATR report submitted? (Y/N) | D9: Y/N | I9: =IF(AND(ISNUMBER(G9),ISNUMBER(H9)),H9-G9,"") | J9: =IF(AND(ISNUMBER(E9),E9>0,ISNUMBER(H9)),H9/E9,"") | K9: In Progress | L9: =IF(M9="Yes","🔴 BOTTOM",IF(M9="No","✓ Cleared",IF(Q9="MIN",IF(AND(ISNUMBER(F9),ISNUMBER(H9)),IF(H9<F9*'Master Dashboard'!$B$4,"🔴 LOW",""),""),IF(Q9="MAX",IF(AND(ISNUMBER(F9),ISNUMBER(H9)),IF(H9>F9,"🔴 HIGH",""),""),"")))) | M9: Auto | P9: STP under construction at MC Raikot | R9: ADCUD-006
A10: 3 | B10: WTP — Water Treatment Plant | C10: WTPs with NO land available | D10: sites | E10: 0 | F10: 0 | H10: 3 | I10: =IF(AND(ISNUMBER(G10),ISNUMBER(H10)),H10-G10,"") | J10: =IF(AND(ISNUMBER(E10),E10>0,ISNUMBER(H10)),H10/E10,"") | K10: Pending/Blocked | L10: =IF(M10="Yes","🔴 BOTTOM",IF(M10="No","✓ Cleared",IF(Q10="MIN",IF(AND(ISNUMBER(F10),ISNUMBER(H10)),IF(H10<F10*'Master Dashboard'!$B$4,"🔴 LOW",""),""),IF(Q10="MAX",IF(AND(ISNUMBER(F10),ISNUMBER(H10)),IF(H10>F10,"🔴 HIGH",""),""),"")))) -> 🔴 HIGH | M10: Auto | N10: Gov Cell (report) | O10: 05-06-2026 | P10: MC Doraha, Maloud, Sahnewal | Q10: MAX | R10: ADCUD-007
C11: Mullanpur Dakha — completion status | D11: status | I11: =IF(AND(ISNUMBER(G11),ISNUMBER(H11)),H11-G11,"") | J11: =IF(AND(ISNUMBER(E11),E11>0,ISNUMBER(H11)),H11/E11,"") | K11: In Progress | L11: =IF(M11="Yes","🔴 BOTTOM",IF(M11="No","✓ Cleared",IF(Q11="MIN",IF(AND(ISNUMBER(F11),ISNUMBER(H11)),IF(H11<F11*'Master Dashboard'!$B$4,"🔴 LOW",""),""),IF(Q11="MAX",IF(AND(ISNUMBER(F11),ISNUMBER(H11)),IF(H11>F11,"🔴 HIGH",""),""),"")))) | M11: Auto | P11: Priority; Council land pending | R11: ADCUD-008
A12: 4 | B12: IT / MC Land Price Fixation | C12: Price Fixation Committee meeting held? (Y/N) | D12: Y/N | I12: =IF(AND(ISNUMBER(G12),ISNUMBER(H12)),H12-G12,"") | J12: =IF(AND(ISNUMBER(E12),E12>0,ISNUMBER(H12)),H12/E12,"") | K12: Pending/Blocked | L12: =IF(M12="Yes","🔴 BOTTOM",IF(M12="No","✓ Cleared",IF(Q12="MIN",IF(AND(ISNUMBER(F12),ISNUMBER(H12)),IF(H12<F12*'Master Dashboard'!$B$4,"🔴 LOW",""),""),IF(Q12="MAX",IF(AND(ISNUMBER(F12),ISNUMBER(H12)),IF(H12>F12,"🔴 HIGH",""),""),"")))) | M12: Auto | P12: IT case under process | R12: ADCUD-009

Sheet ADC (J)
A1: ADC (J) — Priority Agenda Review | DC Ludhiana (MASTER)
A2: Sr | B2: Priority Agenda | C2: KPI / Metric | D2: Concerned Officer / Unit | E2: Target / Total | F2: Flag Bar | G2: Last Value | H2: Current Value | I2: Change | J2: Achieved % | K2: Status | L2: Auto-Flag | M2: Bottom Performer | N2: Updated By | O2: Update Date | P2: Remarks / Context / Pending Action | Q2: Rule | R2: Key
A3: ▣ PRIORITY TASKS — qualitative / assigned tasks
A4: 1 | B4: YnV Bills | C4: Phase I bills — status | D4: bills | I4: =IF(AND(ISNUMBER(G4),ISNUMBER(H4)),H4-G4,"") | J4: =IF(AND(ISNUMBER(E4),E4>0,ISNUMBER(H4)),H4/E4,"") | K4: In Progress | L4: =IF(M4="Yes","🔴 BOTTOM",IF(M4="No","✓ Cleared",IF(Q4="MIN",IF(AND(ISNUMBER(F4),ISNUMBER(H4)),IF(H4<F4*'Master Dashboard'!$B$4,"🔴 LOW",""),""),IF(Q4="MAX",IF(AND(ISNUMBER(F4),ISNUMBER(H4)),IF(H4>F4,"🔴 HIGH",""),""),"")))) | M4: Auto | P4: Phase 1 complete; Phase 2 mtg 5/6 Jun | R4: ADCJ-001
C5: Phase III — E-rickshaws on road | D5: no. | E5: 4 | F5: 4 | H5: 4 | I5: =IF(AND(ISNUMBER(G5),ISNUMBER(H5)),H5-G5,"") | J5: =IF(AND(ISNUMBER(E5),E5>0,ISNUMBER(H5)),H5/E5,"") -> 1 | K5: In Progress | L5: =IF(M5="Yes","🔴 BOTTOM",IF(M5="No","✓ Cleared",IF(Q5="MIN",IF(AND(ISNUMBER(F5),ISNUMBER(H5)),IF(H5<F5*'Master Dashboard'!$B$4,"🔴 LOW",""),""),IF(Q5="MAX",IF(AND(ISNUMBER(F5),ISNUMBER(H5)),IF(H5>F5,"🔴 HIGH",""),""),"")))) | M5: Auto | N5: Gov Cell (report) | O5: 05-06-2026 | P5: Campaign started 8 May | Q5: MIN | R5: ADCJ-002
C6: SAARC Knit & PP bills mismatch — meeting held? (Y/N) | D6: Y/N | I6: =IF(AND(ISNUMBER(G6),ISNUMBER(H6)),H6-G6,"") | J6: =IF(AND(ISNUMBER(E6),E6>0,ISNUMBER(H6)),H6/E6,"") | K6: Pending/Blocked | L6: =IF(M6="Yes","🔴 BOTTOM",IF(M6="No","✓ Cleared",IF(Q6="MIN",IF(AND(ISNUMBER(F6),ISNUMBER(H6)),IF(H6<F6*'Master Dashboard'!$B$4,"🔴 LOW",""),""),IF(Q6="MAX",IF(AND(ISNUMBER(F6),ISNUMBER(H6)),IF(H6>F6,"🔴 HIGH",""),""),"")))) | M6: Auto | R6: ADCJ-003
A7: 2 | B7: Halwara Airport | C7: 📊 Infrastructure works completed | H7: 7 | P7: of 38 total; 31 ongoing. Operational target was 15 May; electricity damage noted.
C8: Infrastructure works — completed | D8: works | E8: 38 | F8: 38 | H8: 7 | I8: =IF(AND(ISNUMBER(G8),ISNUMBER(H8)),H8-G8,"") | J8: =IF(AND(ISNUMBER(E8),E8>0,ISNUMBER(H8)),H8/E8,"") -> 0.18421053 | K8: In Progress | L8: =IF(M8="Yes","🔴 BOTTOM",IF(M8="No","✓ Cleared",IF(Q8="MIN",IF(AND(ISNUMBER(F8),ISNUMBER(H8)),IF(H8<F8*'Master Dashboard'!$B$4,"🔴 LOW",""),""),IF(Q8="MAX",IF(AND(ISNUMBER(F8),ISNUMBER(H8)),IF(H8>F8,"🔴 HIGH",""),""),"")))) -> 🔴 LOW | M8: Auto | N8: Gov Cell (report) | O8: 05-06-2026 | P8: 31 ongoing; target 20 May | Q8: MIN | R8: ADCJ-004
C9: Security accommodation — done? (Y/N) | D9: Y/N | H9: Completed | I9: =IF(AND(ISNUMBER(G9),ISNUMBER(H9)),H9-G9,"") | J9: =IF(AND(ISNUMBER(E9),E9>0,ISNUMBER(H9)),H9/E9,"") | K9: Completed | L9: =IF(M9="Yes","🔴 BOTTOM",IF(M9="No","✓ Cleared",IF(Q9="MIN",IF(AND(ISNUMBER(F9),ISNUMBER(H9)),IF(H9<F9*'Master Dashboard'!$B$4,"🔴 LOW",""),""),IF(Q9="MAX",IF(AND(ISNUMBER(F9),ISNUMBER(H9)),IF(H9>F9,"🔴 HIGH",""),""),"")))) | M9: Auto | N9: Gov Cell (report) | O9: 05-06-2026 | P9: Training of personnel ongoing | R9: ADCJ-005
C10: LIAL — VC held? (Y/N) | D10: Y/N | I10: =IF(AND(ISNUMBER(G10),ISNUMBER(H10)),H10-G10,"") | J10: =IF(AND(ISNUMBER(E10),E10>0,ISNUMBER(H10)),H10/E10,"") | K10: Pending/Blocked | L10: =IF(M10="Yes","🔴 BOTTOM",IF(M10="No","✓ Cleared",IF(Q10="MIN",IF(AND(ISNUMBER(F10),ISNUMBER(H10)),IF(H10<F10*'Master Dashboard'!$B$4,"🔴 LOW",""),""),IF(Q10="MAX",IF(AND(ISNUMBER(F10),ISNUMBER(H10)),IF(H10>F10,"🔴 HIGH",""),""),"")))) | M10: Auto | R10: ADCJ-006
A11: 3 | B11: Flood Protection — Bet Area | C11: Bet area desilting — tenders failed | D11: no. | E11: 0 | F11: 0 | H11: 3 | I11: =IF(AND(ISNUMBER(G11),ISNUMBER(H11)),H11-G11,"") | J11: =IF(AND(ISNUMBER(E11),E11>0,ISNUMBER(H11)),H11/E11,"") | K11: Pending/Blocked | L11: =IF(M11="Yes","🔴 BOTTOM",IF(M11="No","✓ Cleared",IF(Q11="MIN",IF(AND(ISNUMBER(F11),ISNUMBER(H11)),IF(H11<F11*'Master Dashboard'!$B$4,"🔴 LOW",""),""),IF(Q11="MAX",IF(AND(ISNUMBER(F11),ISNUMBER(H11)),IF(H11>F11,"🔴 HIGH",""),""),"")))) -> 🔴 HIGH | M11: Auto | N11: Gov Cell (report) | O11: 05-06-2026 | P11: 8 kila; next date 22 May | Q11: MAX | R11: ADCJ-007
C12: Khaira Bet — forest objections | D12: no. | E12: 0 | F12: 0 | H12: 8 | I12: =IF(AND(ISNUMBER(G12),ISNUMBER(H12)),H12-G12,"") | J12: =IF(AND(ISNUMBER(E12),E12>0,ISNUMBER(H12)),H12/E12,"") | K12: Pending/Blocked | L12: =IF(M12="Yes","🔴 BOTTOM",IF(M12="No","✓ Cleared",IF(Q12="MIN",IF(AND(ISNUMBER(F12),ISNUMBER(H12)),IF(H12<F12*'Master Dashboard'!$B$4,"🔴 LOW",""),""),IF(Q12="MAX",IF(AND(ISNUMBER(F12),ISNUMBER(H12)),IF(H12>F12,"🔴 HIGH",""),""),"")))) -> 🔴 HIGH | M12: Auto | N12: Gov Cell (report) | O12: 05-06-2026 | P12: Forest land; meeting 4 Jun | Q12: MAX | R12: ADCJ-008
C13: DDMA flood equipment (Rs5L Red Cross) — tender floated? (Y/N) | D13: Y/N | I13: =IF(AND(ISNUMBER(G13),ISNUMBER(H13)),H13-G13,"") | J13: =IF(AND(ISNUMBER(E13),E13>0,ISNUMBER(H13)),H13/E13,"") | K13: In Progress | L13: =IF(M13="Yes","🔴 BOTTOM",IF(M13="No","✓ Cleared",IF(Q13="MIN",IF(AND(ISNUMBER(F13),ISNUMBER(H13)),IF(H13<F13*'Master Dashboard'!$B$4,"🔴 LOW",""),""),IF(Q13="MAX",IF(AND(ISNUMBER(F13),ISNUMBER(H13)),IF(H13>F13,"🔴 HIGH",""),""),"")))) | M13: Auto | P13: XEN Kamaljit specs; whole district | R13: ADCJ-009
A14: 4 | B14: Desilting — Khaira Bet Coordination | C14: Escalation to Central Govt / WRD — status | D14: status | I14: =IF(AND(ISNUMBER(G14),ISNUMBER(H14)),H14-G14,"") | J14: =IF(AND(ISNUMBER(E14),E14>0,ISNUMBER(H14)),H14/E14,"") | K14: Pending/Blocked | L14: =IF(M14="Yes","🔴 BOTTOM",IF(M14="No","✓ Cleared",IF(Q14="MIN",IF(AND(ISNUMBER(F14),ISNUMBER(H14)),IF(H14<F14*'Master Dashboard'!$B$4,"🔴 LOW",""),""),IF(Q14="MAX",IF(AND(ISNUMBER(F14),ISNUMBER(H14)),IF(H14>F14,"🔴 HIGH",""),""),"")))) | M14: Auto | P14: NGT next date pending | R14: ADCJ-010
A15: 5 | B15: SPCA | C15: CAPEX funds plan prepared? (Y/N) | D15: Y/N | I15: =IF(AND(ISNUMBER(G15),ISNUMBER(H15)),H15-G15,"") | J15: =IF(AND(ISNUMBER(E15),E15>0,ISNUMBER(H15)),H15/E15,"") | K15: Pending/Blocked | L15: =IF(M15="Yes","🔴 BOTTOM",IF(M15="No","✓ Cleared",IF(Q15="MIN",IF(AND(ISNUMBER(F15),ISNUMBER(H15)),IF(H15<F15*'Master Dashboard'!$B$4,"🔴 LOW",""),""),IF(Q15="MAX",IF(AND(ISNUMBER(F15),ISNUMBER(H15)),IF(H15>F15,"🔴 HIGH",""),""),"")))) | M15: Auto | P15: ADC Jagraon recommendation pending | R15: ADCJ-011
A16: 6 | B16: Raikot Master Plan | C16: Master Plan — status | D16: status | I16: =IF(AND(ISNUMBER(G16),ISNUMBER(H16)),H16-G16,"") | J16: =IF(AND(ISNUMBER(E16),E16>0,ISNUMBER(H16)),H16/E16,"") | K16: In Progress | L16: =IF(M16="Yes","🔴 BOTTOM",IF(M16="No","✓ Cleared",IF(Q16="MIN",IF(AND(ISNUMBER(F16),ISNUMBER(H16)),IF(H16<F16*'Master Dashboard'!$B$4,"🔴 LOW",""),""),IF(Q16="MAX",IF(AND(ISNUMBER(F16),ISNUMBER(H16)),IF(H16>F16,"🔴 HIGH",""),""),"")))) | M16: Auto | P16: Update pending | R16: ADCJ-012

Sheet ADC (K)
A1: ADC (K) — Priority Agenda Review | DC Ludhiana (MASTER)
A2: Sr | B2: Priority Agenda | C2: KPI / Metric | D2: Concerned Officer / Unit | E2: Target / Total | F2: Flag Bar | G2: Last Value | H2: Current Value | I2: Change | J2: Achieved % | K2: Status | L2: Auto-Flag | M2: Bottom Performer | N2: Updated By | O2: Update Date | P2: Remarks / Context / Pending Action | Q2: Rule | R2: Key
A3: ▣ PRIORITY TASKS — qualitative / assigned tasks
A4: 1 | B4: Court Cases & Legal Matters | C4: Hadon Bet (YnV) — CM Relief Fund status | D4: status | I4: =IF(AND(ISNUMBER(G4),ISNUMBER(H4)),H4-G4,"") | J4: =IF(AND(ISNUMBER(E4),E4>0,ISNUMBER(H4)),H4/E4,"") | K4: Pending/Blocked | L4: =IF(M4="Yes","🔴 BOTTOM",IF(M4="No","✓ Cleared",IF(Q4="MIN",IF(AND(ISNUMBER(F4),ISNUMBER(H4)),IF(H4<F4*'Master Dashboard'!$B$4,"🔴 LOW",""),""),IF(Q4="MAX",IF(AND(ISNUMBER(F4),ISNUMBER(H4)),IF(H4>F4,"🔴 HIGH",""),""),"")))) | M4: Auto | P4: Due 13 May — overdue | R4: ADCK-001
C5: No-representation defaults | D5: no. | E5: 0 | F5: 0 | I5: =IF(AND(ISNUMBER(G5),ISNUMBER(H5)),H5-G5,"") | J5: =IF(AND(ISNUMBER(E5),E5>0,ISNUMBER(H5)),H5/E5,"") | K5: In Progress | L5: =IF(M5="Yes","🔴 BOTTOM",IF(M5="No","✓ Cleared",IF(Q5="MIN",IF(AND(ISNUMBER(F5),ISNUMBER(H5)),IF(H5<F5*'Master Dashboard'!$B$4,"🔴 LOW",""),""),IF(Q5="MAX",IF(AND(ISNUMBER(F5),ISNUMBER(H5)),IF(H5>F5,"🔴 HIGH",""),""),"")))) | M5: Auto | P5: Zero tolerance | Q5: MAX | R5: ADCK-002
A6: 2 | B6: Flood Protection — Sasrali | C6: 📊 Sasrali geotubes installed | H6: 51 | P6: of 448 (35%). Work closed 23.05 by XEN Mining; Show-Cause issued. 12 tippers running.
C7: Sasrali geotubes installed | D7: tubes | E7: 448 | F7: 448 | H7: 51 | I7: =IF(AND(ISNUMBER(G7),ISNUMBER(H7)),H7-G7,"") | J7: =IF(AND(ISNUMBER(E7),E7>0,ISNUMBER(H7)),H7/E7,"") -> 0.11383929 | K7: Pending/Blocked | L7: =IF(M7="Yes","🔴 BOTTOM",IF(M7="No","✓ Cleared",IF(Q7="MIN",IF(AND(ISNUMBER(F7),ISNUMBER(H7)),IF(H7<F7*'Master Dashboard'!$B$4,"🔴 LOW",""),""),IF(Q7="MAX",IF(AND(ISNUMBER(F7),ISNUMBER(H7)),IF(H7>F7,"🔴 HIGH",""),""),"")))) -> 🔴 LOW | M7: Auto | N7: Gov Cell (report) | O7: 05-06-2026 | P7: 35% done; closed 23.05 by XEN Mining; SCN issued | Q7: MIN | R7: ADCK-003
